<?xml version="1.0" encoding="UTF-8"?>
<robot name="robot">

<!-- world link -->
<link name="world"/>

<!-- base_link and its fixed joint -->
<joint name="joint_fix" type="fixed">
  <parent link="world"/>
  <child link="base_link"/>
</joint>

  <link name="base_link">
    <inertial>
      <origin
        xyz="5.43344915542855E-09 0.0443960955613357 0.500000172877206"
        rpy="0 0 0" />
      <mass
        value="17.8923575005348" />
      <inertia
        ixx="0"
        ixy="0"
        ixz="0"
        iyy="0"
        iyz="0"
        izz="0" />
    </inertial>
    <visual>
      <origin
        xyz="0 0 0"
        rpy="0 0 0" />
      <geometry>
        <mesh
          filename="package://robot/meshes/base_link.STL" />
      </geometry>
      <material
        name="">
        <color
          rgba="0.780392156862745 0.76078431372549 0.741176470588235 1" />
      </material>
    </visual>
    <collision>
      <origin
        xyz="0 0 0"
        rpy="0 0 0" />
      <geometry>
        <mesh
          filename="package://robot/meshes/base_link.STL" />
      </geometry>
    </collision>
  </link>

  <link name="link1">
    <inertial>
      <origin
        xyz="1.68454688766964E-07 0.164275740780367 -0.0669943121573495"
        rpy="0 0 0" />
      <mass
        value="19.3943177662416" />
      <inertia
        ixx="0"
        ixy="0"
        ixz="0"
        iyy="0"
        iyz="0"
        izz="0" />
    </inertial>
    <visual>
      <origin
        xyz="0 0 0"
        rpy="0 0 0" />
      <geometry>
        <mesh
          filename="package://robot/meshes/link1.STL" />
      </geometry>
      <material
        name="">
        <color
          rgba="0.780392156862745 0.76078431372549 0.741176470588235 1" />
      </material>
    </visual>
    <collision>
      <origin
        xyz="0 0 0"
        rpy="0 0 0" />
      <geometry>
        <mesh
          filename="package://robot/meshes/link1.STL" />
      </geometry>
    </collision>
  </link>

  <joint name="joint1" type="continuous">
    <origin
      xyz="0 -0.5 0.11"
      rpy="1.5707963267949 0 0" />
    <parent
      link="base_link" />
    <child
      link="link1" />
    <axis
      xyz="0 1 0" />
  </joint>

  <link name="link2">
    <inertial>
      <origin
        xyz="0.0328384782772146 0.274326458730003 3.31679128606766E-14"
        rpy="0 0 0" />
      <mass
        value="20.8227875150365" />
      <inertia
        ixx="0"
        ixy="0"
        ixz="0"
        iyy="0"
        iyz="0"
        izz="0" />
    </inertial>
    <visual>
      <origin
        xyz="0 0 0"
        rpy="0 0 0" />
      <geometry>
        <mesh
          filename="package://robot/meshes/link2.STL" />
      </geometry>
      <material
        name="">
        <color
          rgba="0.909803921568627 0.443137254901961 0.0313725490196078 1" />
      </material>
    </visual>
    <collision>
      <origin
        xyz="0 0 0"
        rpy="0 0 0" />
      <geometry>
        <mesh
          filename="package://robot/meshes/link2.STL" />
      </geometry>
    </collision>
  </link>

  <joint
    name="joint2"
    type="continuous">
    <origin
      xyz="0 0.322732802998902 -0.250383739680009"
      rpy="0 0 0" />
    <parent
      link="link1" />
    <child
      link="link2" />
    <axis
      xyz="1 0 0" />
  </joint>
  <link
    name="link3">
    <inertial>
      <origin
        xyz="0.0361839079462923 2.09127868135983E-05 -0.185012067507171"
        rpy="0 0 0" />
      <mass
        value="13.649633544176" />
      <inertia
        ixx="0"
        ixy="0"
        ixz="0"
        iyy="0"
        iyz="0"
        izz="0" />
    </inertial>
    <visual>
      <origin
        xyz="0 0 0"
        rpy="0 0 0" />
      <geometry>
        <mesh
          filename="package://robot/meshes/link3.STL" />
      </geometry>
      <material
        name="">
        <color
          rgba="0.909803921568627 0.443137254901961 0.0313725490196078 1" />
      </material>
    </visual>
    <collision>
      <origin
        xyz="0 0 0"
        rpy="0 0 0" />
      <geometry>
        <mesh
          filename="package://robot/meshes/link3.STL" />
      </geometry>
    </collision>
  </link>
  <joint
    name="joint3"
    type="continuous">
    <origin
      xyz="0 0.777773579919563 0"
      rpy="0 0 0" />
    <parent
      link="link2" />
    <child
      link="link3" />
    <axis
      xyz="1 0 0" />
  </joint>
  <link
    name="link4">
    <inertial>
      <origin
        xyz="2.22044604925031E-16 1.38777878078145E-17 -0.143700987107576"
        rpy="0 0 0" />
      <mass
        value="3.83524054978555" />
      <inertia
        ixx="0"
        ixy="0"
        ixz="0"
        iyy="0"
        iyz="0"
        izz="0" />
    </inertial>
    <visual>
      <origin
        xyz="0 0 0"
        rpy="0 0 0" />
      <geometry>
        <mesh
          filename="package://robot/meshes/link4.STL" />
      </geometry>
      <material
        name="">
        <color
          rgba="0.909803921568627 0.443137254901961 0.0313725490196078 1" />
      </material>
    </visual>
    <collision>
      <origin
        xyz="0 0 0"
        rpy="0 0 0" />
      <geometry>
        <mesh
          filename="package://robot/meshes/link4.STL" />
      </geometry>
    </collision>
  </link>
  <joint
    name="joint4"
    type="continuous">
    <origin
      xyz="0.0483407685108506 0 -0.603280829801762"
      rpy="0 0 -1.5707963267949" />
    <parent
      link="link3" />
    <child
      link="link4" />
    <axis
      xyz="-1 0 0" />
  </joint>

  <gazebo reference="base_link">
    <material>Gazebo/Black</material>
  </gazebo>
  <gazebo reference="link1">
    <material>Gazebo/Orange</material>
  </gazebo>
  <gazebo reference="link2">
    <material>Gazebo/Orange</material>
  </gazebo>
  <gazebo reference="link3">
    <material>Gazebo/Orange</material>
  </gazebo>
  <gazebo reference="link4">
    <material>Gazebo/Red</material>
  </gazebo>
</robot>